Workbook

Sheet Data
A1: Accessibility ID — Ham Veri (Tüm Sayfalar)
A2: Element ID | B2: Page | C2: Type | D2: Label / Text | E2: Value | F2: Resource ID | G2: Status
A3: bookaflight_element_1 | B3: MainActivity | C3: ViewGroup | F3: avail_search_header | G3: ID Var
A4: bookaflight_element_2 | B4: MainActivity | C4: ViewGroup | D4: Departure, Select | F4: avail_search_dep_port_card | G4: ID Var
A5: bookaflight_element_3 | B5: MainActivity | C5: ViewGroup | D5: Arrival, Select | F5: avail_search_arr_port_card | G5: ID Var
A6: bookaflight_element_4 | B6: MainActivity | C6: ViewGroup | D6: Departure Date, Select | F6: avail_search_dep_date_card | G6: ID Var
A7: bookaflight_element_5 | B7: MainActivity | C7: ViewGroup | D7: One Way | F7: avail_selection_switch_item | G7: Duplicate
A8: bookaflight_element_6 | B8: MainActivity | C8: ViewGroup | D8: Round Trip | F8: avail_selection_switch_item | G8: Duplicate
A9: bookaflight_element_7 | B9: MainActivity | C9: ViewGroup | D9: Multi City | F9: avail_selection_switch_item | G9: Duplicate
A10: bookaflight_element_8 | B10: MainActivity | C10: ViewGroup | D10: Passengers, 1 Adult | F10: avail_search_pax_count_card | G10: Duplicate
A11: bookaflight_element_9 | B11: MainActivity | C11: ViewGroup | D11: Class, Economy | F11: avail_search_pax_count_card | G11: Duplicate
A12: bookaflight_element_10 | B12: MainActivity | C12: View | D12: Home | G12: ID Yok
A13: bookaflight_element_11 | B13: MainActivity | C13: View | D13: Book | G13: ID Yok
A14: bookaflight_element_12 | B14: MainActivity | C14: View | D14: Manage | G14: ID Yok
A15: bookaflight_element_13 | B15: MainActivity | C15: View | D15: Check-in | G15: ID Yok
A16: bookaflight_element_14 | B16: MainActivity | C16: View | D16: Profile | G16: ID Yok
A17: bookaflight_element_15 | B17: MainActivity | C17: ViewGroup | D17: Information for Credit Card Holders | G17: ID Yok
A18: mbSearch_element_1 | B18: MainActivity | C18: EditText | D18: Surname | E18: Surname | F18: mbk_search_text_field_surname | G18: ID Var
A19: mbSearch_element_2 | B19: MainActivity | C19: EditText | D19: Enter | E19: Enter | F19: mbk_search_text_field_bookingId | G19: ID Var
A20: mbSearch_element_3 | B20: MainActivity | C20: ViewGroup | D20: Manage | F20: mbk_search_find_button | G20: ID Var
A21: mbSearch_element_4 | B21: MainActivity | C21: TextView | D21: Manage Booking | E21: Manage Booking | F21: mbk_search_header | G21: ID Var
A22: mbSearch_element_5 | B22: MainActivity | C22: View | D22: Home | G22: ID Yok
A23: mbSearch_element_6 | B23: MainActivity | C23: View | D23: Book | G23: ID Yok
A24: mbSearch_element_7 | B24: MainActivity | C24: View | D24: Manage | G24: ID Yok
A25: mbSearch_element_8 | B25: MainActivity | C25: View | D25: Check-in | G25: ID Yok
A26: mbSearch_element_9 | B26: MainActivity | C26: View | D26: Profile | G26: ID Yok
A27: mbSearch_element_10 | B27: MainActivity | C27: ViewGroup | D27: Long Lon Long Operational Notice One Two | G27: ID Yok
A28: profile_element_1 | B28: MainActivity | C28: EditText | D28: Enter | E28: Enter | F28: loyalty_login_text_field_emailOrMembership | G28: ID Var
A29: profile_element_2 | B29: MainActivity | C29: EditText | D29: Enter | E29: Enter | F29: loyalty_login_text_field_password | G29: ID Var
A30: profile_element_3 | B30: MainActivity | C30: ViewGroup | F30: loyalty_login_header | G30: ID Var
A31: profile_element_4 | B31: MainActivity | C31: ViewGroup | D31: Log in | F31: loyalty_login_login_button | G31: ID Var
A32: profile_element_5 | B32: MainActivity | C32: View | D32: Home | G32: ID Yok
A33: profile_element_6 | B33: MainActivity | C33: View | D33: Book | G33: ID Yok
A34: profile_element_7 | B34: MainActivity | C34: View | D34: Manage | G34: ID Yok
A35: profile_element_8 | B35: MainActivity | C35: View | D35: Check-in | G35: ID Yok
A36: profile_element_9 | B36: MainActivity | C36: View | D36: Profile | G36: ID Yok
A37: profile_element_10 | B37: MainActivity | C37: ViewGroup | D37: Long Lon Long Operational Notice One Two | G37: ID Yok
A38: profile_element_11 | B38: MainActivity | C38: ViewGroup | D38: Remember Me | G38: ID Yok
A39: profile_element_12 | B39: MainActivity | C39: ViewGroup | D39: Forgot Password? | G39: ID Yok
A40: profile_element_13 | B40: MainActivity | C40: ViewGroup | D40: Sign Up | G40: ID Yok
...

Sheet Summary
A1: Accessibility ID — Özet Rapor
A3: ID Yok | B3: Undefined ID | C3: Duplicate | D3: ID Var
A4: 26 | B4: 5 | C4: 5 | D4: 12
A5: %54 | B5: %10 | C5: %10 | D5: %25
A7: Sayfa Bazlı Dağılım
A8: Sayfa | B8: ID Yok | C8: Undefined ID | D8: Duplicate | E8: ID Var | F8: Toplam
A9: bookaflight | B9: 6 | C9: 0 | D9: 5 | E9: 4 | F9: 15
A10: mbSearch | B10: 6 | C10: 0 | D10: 0 | E10: 4 | F10: 10
A11: profile | B11: 9 | C11: 0 | D11: 0 | E11: 4 | F11: 13
A12: signup | B12: 5 | C12: 5 | D12: 0 | E12: 0 | F12: 10
A13: TOPLAM | B13: 26 | C13: 5 | D13: 5 | E13: 12 | F13: 48

Sheet Task
A1: ID Eklenecek Elementler — Waiting Dev (36 adet)
A2: Element ID | B2: Page | C2: Type | D2: Label / Text | E2: Value | F2: Resource ID | G2: Status | H2: New Status
A3: bookaflight_element_5 | B3: MainActivity | C3: ViewGroup | D3: One Way | F3: avail_selection_switch_item | G3: Duplicate | H3: =bookaflight!H7 -> ID Eklenecek (Waiting Dev)
A4: bookaflight_element_6 | B4: MainActivity | C4: ViewGroup | D4: Round Trip | F4: avail_selection_switch_item | G4: Duplicate | H4: =bookaflight!H8 -> ID Eklenecek (Waiting Dev)
A5: bookaflight_element_7 | B5: MainActivity | C5: ViewGroup | D5: Multi City | F5: avail_selection_switch_item | G5: Duplicate | H5: =bookaflight!H9 -> ID Eklenecek (Waiting Dev)
A6: bookaflight_element_8 | B6: MainActivity | C6: ViewGroup | D6: Passengers, 1 Adult | F6: avail_search_pax_count_card | G6: Duplicate | H6: =bookaflight!H10 -> ID Eklenecek (Waiting Dev)
A7: bookaflight_element_9 | B7: MainActivity | C7: ViewGroup | D7: Class, Economy | F7: avail_search_pax_count_card | G7: Duplicate | H7: =bookaflight!H11 -> ID Eklenecek (Waiting Dev)
A8: bookaflight_element_10 | B8: MainActivity | C8: View | D8: Home | G8: ID Yok | H8: =bookaflight!H12 -> ID Eklenecek (Waiting Dev)
A9: bookaflight_element_11 | B9: MainActivity | C9: View | D9: Book | G9: ID Yok | H9: =bookaflight!H13 -> ID Eklenecek (Waiting Dev)
A10: bookaflight_element_12 | B10: MainActivity | C10: View | D10: Manage | G10: ID Yok | H10: =bookaflight!H14 -> ID Eklenecek (Waiting Dev)
A11: bookaflight_element_13 | B11: MainActivity | C11: View | D11: Check-in | G11: ID Yok | H11: =bookaflight!H15 -> ID Eklenecek (Waiting Dev)
A12: bookaflight_element_14 | B12: MainActivity | C12: View | D12: Profile | G12: ID Yok | H12: =bookaflight!H16 -> ID Eklenecek (Waiting Dev)
A13: bookaflight_element_15 | B13: MainActivity | C13: ViewGroup | D13: Information for Credit Card Holders | G13: ID Yok | H13: =bookaflight!H17 -> ID Eklenecek (Waiting Dev)
A14: mbSearch_element_5 | B14: MainActivity | C14: View | D14: Home | G14: ID Yok | H14: =mbSearch!H7 -> ID Eklenecek (Waiting Dev)
A15: mbSearch_element_6 | B15: MainActivity | C15: View | D15: Book | G15: ID Yok | H15: =mbSearch!H8 -> ID Eklenecek (Waiting Dev)
A16: mbSearch_element_7 | B16: MainActivity | C16: View | D16: Manage | G16: ID Yok | H16: =mbSearch!H9 -> ID Eklenecek (Waiting Dev)
A17: mbSearch_element_8 | B17: MainActivity | C17: View | D17: Check-in | G17: ID Yok | H17: =mbSearch!H10 -> ID Eklenecek (Waiting Dev)
A18: mbSearch_element_9 | B18: MainActivity | C18: View | D18: Profile | G18: ID Yok | H18: =mbSearch!H11 -> ID Eklenecek (Waiting Dev)
A19: mbSearch_element_10 | B19: MainActivity | C19: ViewGroup | D19: Long Lon Long Operational Notice One Two | G19: ID Yok | H19: =mbSearch!H12 -> ID Eklenecek (Waiting Dev)
A20: profile_element_5 | B20: MainActivity | C20: View | D20: Home | G20: ID Yok | H20: =profile!H7 -> ID Eklenecek (Waiting Dev)
A21: profile_element_6 | B21: MainActivity | C21: View | D21: Book | G21: ID Yok | H21: =profile!H8 -> ID Eklenecek (Waiting Dev)
A22: profile_element_7 | B22: MainActivity | C22: View | D22: Manage | G22: ID Yok | H22: =profile!H9 -> ID Eklenecek (Waiting Dev)
A23: profile_element_8 | B23: MainActivity | C23: View | D23: Check-in | G23: ID Yok | H23: =profile!H10 -> ID Eklenecek (Waiting Dev)
A24: profile_element_9 | B24: MainActivity | C24: View | D24: Profile | G24: ID Yok | H24: =profile!H11 -> ID Eklenecek (Waiting Dev)
A25: profile_element_10 | B25: MainActivity | C25: ViewGroup | D25: Long Lon Long Operational Notice One Two | G25: ID Yok | H25: =profile!H12 -> ID Eklenecek (Waiting Dev)
A26: profile_element_11 | B26: MainActivity | C26: ViewGroup | D26: Remember Me | G26: ID Yok | H26: =profile!H13 -> ID Eklenecek (Waiting Dev)
A27: profile_element_12 | B27: MainActivity | C27: ViewGroup | D27: Forgot Password? | G27: ID Yok | H27: =profile!H14 -> ID Eklenecek (Waiting Dev)
A28: profile_element_13 | B28: MainActivity | C28: ViewGroup | D28: Sign Up | G28: ID Yok | H28: =profile!H15 -> ID Eklenecek (Waiting Dev)
A29: signup_element_1 | B29: MainActivity | C29: EditText | D29: Enter | E29: Enter | F29: undefinedgivenName | G29: Undefined ID | H29: =signup!H3 -> ID Eklenecek (Waiting Dev)
A30: signup_element_2 | B30: MainActivity | C30: EditText | D30: Surname | E30: Surname | F30: undefinedsurname | G30: Undefined ID | H30: =signup!H4 -> ID Eklenecek (Waiting Dev)
A31: signup_element_3 | B31: MainActivity | C31: ViewGroup | F31: undefinedtitle | G31: Undefined ID | H31: =signup!H5 -> ID Eklenecek (Waiting Dev)
A32: signup_element_4 | B32: MainActivity | C32: ViewGroup | D32: Date of Birth* | F32: undefinedbirthDate | G32: Undefined ID | H32: =signup!H6 -> ID Eklenecek (Waiting Dev)
A33: signup_element_5 | B33: MainActivity | C33: ViewGroup | D33: Nationality* | F33: undefinednationality | G33: Undefined ID | H33: =signup!H7 -> ID Eklenecek (Waiting Dev)
A34: signup_element_6 | B34: MainActivity | C34: EditText | D34: Enter | E34: Enter | G34: ID Yok | H34: =signup!H8 -> ID Eklenecek (Waiting Dev)
A35: signup_element_7 | B35: MainActivity | C35: EditText | D35: Select | E35: Select | G35: ID Yok | H35: =signup!H9 -> ID Eklenecek (Waiting Dev)
A36: signup_element_8 | B36: MainActivity | C36: EditText | D36: Enter | E36: Enter | G36: ID Yok | H36: =signup!H10 -> ID Eklenecek (Waiting Dev)
A37: signup_element_9 | B37: MainActivity | C37: ViewGroup | D37: Male | G37: ID Yok | H37: =signup!H11 -> ID Eklenecek (Waiting Dev)
A38: signup_element_10 | B38: MainActivity | C38: ViewGroup | D38: Female | G38: ID Yok | H38: =signup!H12 -> ID Eklenecek (Waiting Dev)

Sheet bookaflight
A1: bookaflight | 16.04.2026 14:40 | ANDROID | J1: 📸 bookaflight
A2: Element ID | B2: Page | C2: Type | D2: Label / Text | E2: Value | F2: Resource ID | G2: Status | H2: New Status
A3: bookaflight_element_1 | B3: MainActivity | C3: ViewGroup | F3: avail_search_header | G3: ID Var
A4: bookaflight_element_2 | B4: MainActivity | C4: ViewGroup | D4: Departure, Select | F4: avail_search_dep_port_card | G4: ID Var
A5: bookaflight_element_3 | B5: MainActivity | C5: ViewGroup | D5: Arrival, Select | F5: avail_search_arr_port_card | G5: ID Var
A6: bookaflight_element_4 | B6: MainActivity | C6: ViewGroup | D6: Departure Date, Select | F6: avail_search_dep_date_card | G6: ID Var
A7: bookaflight_element_5 | B7: MainActivity | C7: ViewGroup | D7: One Way | F7: avail_selection_switch_item | G7: Duplicate | H7: ID Eklenecek (Waiting Dev)
A8: bookaflight_element_6 | B8: MainActivity | C8: ViewGroup | D8: Round Trip | F8: avail_selection_switch_item | G8: Duplicate | H8: ID Eklenecek (Waiting Dev)
A9: bookaflight_element_7 | B9: MainActivity | C9: ViewGroup | D9: Multi City | F9: avail_selection_switch_item | G9: Duplicate | H9: ID Eklenecek (Waiting Dev)
A10: bookaflight_element_8 | B10: MainActivity | C10: ViewGroup | D10: Passengers, 1 Adult | F10: avail_search_pax_count_card | G10: Duplicate | H10: ID Eklenecek (Waiting Dev)
A11: bookaflight_element_9 | B11: MainActivity | C11: ViewGroup | D11: Class, Economy | F11: avail_search_pax_count_card | G11: Duplicate | H11: ID Eklenecek (Waiting Dev)
A12: bookaflight_element_10 | B12: MainActivity | C12: View | D12: Home | G12: ID Yok | H12: ID Eklenecek (Waiting Dev)
A13: bookaflight_element_11 | B13: MainActivity | C13: View | D13: Book | G13: ID Yok | H13: ID Eklenecek (Waiting Dev)
A14: bookaflight_element_12 | B14: MainActivity | C14: View | D14: Manage | G14: ID Yok | H14: ID Eklenecek (Waiting Dev)
A15: bookaflight_element_13 | B15: MainActivity | C15: View | D15: Check-in | G15: ID Yok | H15: ID Eklenecek (Waiting Dev)
A16: bookaflight_element_14 | B16: MainActivity | C16: View | D16: Profile | G16: ID Yok | H16: ID Eklenecek (Waiting Dev)
A17: bookaflight_element_15 | B17: MainActivity | C17: ViewGroup | D17: Information for Credit Card Holders | G17: ID Yok | H17: ID Eklenecek (Waiting Dev)

Sheet mbSearch
A1: mbSearch | 16.04.2026 14:47 | ANDROID | J1: 📸 mbSearch
A2: Element ID | B2: Page | C2: Type | D2: Label / Text | E2: Value | F2: Resource ID | G2: Status | H2: New Status
A3: mbSearch_element_1 | B3: MainActivity | C3: EditText | D3: Surname | E3: Surname | F3: mbk_search_text_field_surname | G3: ID Var
A4: mbSearch_element_2 | B4: MainActivity | C4: EditText | D4: Enter | E4: Enter | F4: mbk_search_text_field_bookingId | G4: ID Var
A5: mbSearch_element_3 | B5: MainActivity | C5: ViewGroup | D5: Manage | F5: mbk_search_find_button | G5: ID Var
A6: mbSearch_element_4 | B6: MainActivity | C6: TextView | D6: Manage Booking | E6: Manage Booking | F6: mbk_search_header | G6: ID Var
A7: mbSearch_element_5 | B7: MainActivity | C7: View | D7: Home | G7: ID Yok | H7: ID Eklenecek (Waiting Dev)
A8: mbSearch_element_6 | B8: MainActivity | C8: View | D8: Book | G8: ID Yok | H8: ID Eklenecek (Waiting Dev)
A9: mbSearch_element_7 | B9: MainActivity | C9: View | D9: Manage | G9: ID Yok | H9: ID Eklenecek (Waiting Dev)
A10: mbSearch_element_8 | B10: MainActivity | C10: View | D10: Check-in | G10: ID Yok | H10: ID Eklenecek (Waiting Dev)
A11: mbSearch_element_9 | B11: MainActivity | C11: View | D11: Profile | G11: ID Yok | H11: ID Eklenecek (Waiting Dev)
A12: mbSearch_element_10 | B12: MainActivity | C12: ViewGroup | D12: Long Lon Long Operational Notice One Two | G12: ID Yok | H12: ID Eklenecek (Waiting Dev)

Sheet profile
A1: profile | 16.04.2026 14:48 | ANDROID | J1: 📸 profile
A2: Element ID | B2: Page | C2: Type | D2: Label / Text | E2: Value | F2: Resource ID | G2: Status | H2: New Status
A3: profile_element_1 | B3: MainActivity | C3: EditText | D3: Enter | E3: Enter | F3: loyalty_login_text_field_emailOrMembership | G3: ID Var
A4: profile_element_2 | B4: MainActivity | C4: EditText | D4: Enter | E4: Enter | F4: loyalty_login_text_field_password | G4: ID Var
A5: profile_element_3 | B5: MainActivity | C5: ViewGroup | F5: loyalty_login_header | G5: ID Var
A6: profile_element_4 | B6: MainActivity | C6: ViewGroup | D6: Log in | F6: loyalty_login_login_button | G6: ID Var
A7: profile_element_5 | B7: MainActivity | C7: View | D7: Home | G7: ID Yok | H7: ID Eklenecek (Waiting Dev)
A8: profile_element_6 | B8: MainActivity | C8: View | D8: Book | G8: ID Yok | H8: ID Eklenecek (Waiting Dev)
A9: profile_element_7 | B9: MainActivity | C9: View | D9: Manage | G9: ID Yok | H9: ID Eklenecek (Waiting Dev)
A10: profile_element_8 | B10: MainActivity | C10: View | D10: Check-in | G10: ID Yok | H10: ID Eklenecek (Waiting Dev)
A11: profile_element_9 | B11: MainActivity | C11: View | D11: Profile | G11: ID Yok | H11: ID Eklenecek (Waiting Dev)
A12: profile_element_10 | B12: MainActivity | C12: ViewGroup | D12: Long Lon Long Operational Notice One Two | G12: ID Yok | H12: ID Eklenecek (Waiting Dev)
A13: profile_element_11 | B13: MainActivity | C13: ViewGroup | D13: Remember Me | G13: ID Yok | H13: ID Eklenecek (Waiting Dev)
A14: profile_element_12 | B14: MainActivity | C14: ViewGroup | D14: Forgot Password? | G14: ID Yok | H14: ID Eklenecek (Waiting Dev)
A15: profile_element_13 | B15: MainActivity | C15: ViewGroup | D15: Sign Up | G15: ID Yok | H15: ID Eklenecek (Waiting Dev)

Sheet signup
A1: signup | 16.04.2026 14:49 | ANDROID | J1: 📸 signup
A2: Element ID | B2: Page | C2: Type | D2: Label / Text | E2: Value | F2: Resource ID | G2: Status | H2: New Status
A3: signup_element_1 | B3: MainActivity | C3: EditText | D3: Enter | E3: Enter | F3: undefinedgivenName | G3: Undefined ID | H3: ID Eklenecek (Waiting Dev)
A4: signup_element_2 | B4: MainActivity | C4: EditText | D4: Surname | E4: Surname | F4: undefinedsurname | G4: Undefined ID | H4: ID Eklenecek (Waiting Dev)
A5: signup_element_3 | B5: MainActivity | C5: ViewGroup | F5: undefinedtitle | G5: Undefined ID | H5: ID Eklenecek (Waiting Dev)
A6: signup_element_4 | B6: MainActivity | C6: ViewGroup | D6: Date of Birth* | F6: undefinedbirthDate | G6: Undefined ID | H6: ID Eklenecek (Waiting Dev)
A7: signup_element_5 | B7: MainActivity | C7: ViewGroup | D7: Nationality* | F7: undefinednationality | G7: Undefined ID | H7: ID Eklenecek (Waiting Dev)
A8: signup_element_6 | B8: MainActivity | C8: EditText | D8: Enter | E8: Enter | G8: ID Yok | H8: ID Eklenecek (Waiting Dev)
A9: signup_element_7 | B9: MainActivity | C9: EditText | D9: Select | E9: Select | G9: ID Yok | H9: ID Eklenecek (Waiting Dev)
A10: signup_element_8 | B10: MainActivity | C10: EditText | D10: Enter | E10: Enter | G10: ID Yok | H10: ID Eklenecek (Waiting Dev)
A11: signup_element_9 | B11: MainActivity | C11: ViewGroup | D11: Male | G11: ID Yok | H11: ID Eklenecek (Waiting Dev)
A12: signup_element_10 | B12: MainActivity | C12: ViewGroup | D12: Female | G12: ID Yok | H12: ID Eklenecek (Waiting Dev)
