Workbook

Sheet Data
A1: Accessibility ID — Ham Veri (Tüm Sayfalar)
A2: Element ID | B2: Page | C2: Type | D2: Label / Text | E2: Value | F2: Resource ID | G2: Status | H2: AI Suggestion
A3: roomSearch_element_1 | B3: SearchActivity | C3: ViewGroup | F3: facet_with_bui_booking_header_toolbar | G3: Unique ID | H3: { "key": "facetWithBuiBookingHeaderToolbarContainer", "androidValue": "facet_with_bui_booking_header_toolbar", "androidType": "id", "iosValue": "facet_with_bui_booking_header_toolbar", "iosType": "accessibilityId" }
A4: roomSearch_element_2 | B4: SearchActivity | C4: TextView | D4: 1 | E4: 1 | F4: bubble | G4: Unique ID | H4: { "key": "bubbleLabel", "androidValue": "bubble", "androidType": "id", "iosValue": "bubble", "iosType": "accessibilityId" }
A5: roomSearch_element_3 | B5: SearchActivity | C5: TextView | D5: Search | E5: Search | F5: navigation_bar_item_large_label_view | G5: Unique ID | H5: { "key": "navigationBarItemLargeLabelViewLabel", "androidValue": "navigation_bar_item_large_label_view", "androidType": "id", "iosValue": "navigation_bar_item_large_label_view", "iosType": "accessibilityId" }
A6: roomSearch_element_4 | B6: SearchActivity | C6: ImageView | F6: facet_entry_point_item_icon | G6: Duplicate ID | H6: facet_entry_point_item_icon_room
A7: roomSearch_element_5 | B7: SearchActivity | C7: ImageView | F7: facet_entry_point_item_icon | G7: Duplicate ID | H7: facet_entry_point_item_icon_car
A8: roomSearch_element_6 | B8: SearchActivity | C8: ImageView | F8: facet_entry_point_item_icon | G8: Duplicate ID | H8: facet_entry_point_item_icon_taxi
A9: roomSearch_element_7 | B9: SearchActivity | C9: ImageView | F9: facet_entry_point_item_icon | G9: Duplicate ID | H9: imageview_icon
A10: roomSearch_element_8 | B10: SearchActivity | C10: ImageView | F10: navigation_bar_item_icon_view | G10: Duplicate ID | H10: imageview_icon
A11: roomSearch_element_9 | B11: SearchActivity | C11: ImageView | F11: navigation_bar_item_icon_view | G11: Duplicate ID | H11: imageview_icon
A12: roomSearch_element_10 | B12: SearchActivity | C12: ImageView | F12: navigation_bar_item_icon_view | G12: Duplicate ID | H12: imageview_icon
A13: roomSearch_element_11 | B13: SearchActivity | C13: ImageView | F13: navigation_bar_item_icon_view | G13: Duplicate ID | H13: imageview_icon
A14: roomSearch_element_12 | B14: SearchActivity | C14: TextView | D14: Stays | E14: Stays | F14: facet_entry_point_item_label | G14: Duplicate ID | H14: stays_label
A15: roomSearch_element_13 | B15: SearchActivity | C15: TextView | D15: Car rental | E15: Car rental | F15: facet_entry_point_item_label | G15: Duplicate ID | H15: car_rental_label
A16: roomSearch_element_14 | B16: SearchActivity | C16: TextView | D16: Taxi | E16: Taxi | F16: facet_entry_point_item_label | G16: Duplicate ID | H16: taxi_label
A17: roomSearch_element_15 | B17: SearchActivity | C17: TextView | D17: Attractions | E17: Attractions | F17: facet_entry_point_item_label | G17: Duplicate ID | H17: attractions_label
A18: roomSearch_element_16 | B18: SearchActivity | C18: TextView | D18: Saved | E18: Saved | F18: navigation_bar_item_small_label_view | G18: Duplicate ID | H18: saved_label
A19: roomSearch_element_17 | B19: SearchActivity | C19: TextView | D19: Bookings | E19: Bookings | F19: navigation_bar_item_small_label_view | G19: Duplicate ID | H19: bookings_label
A20: roomSearch_element_18 | B20: SearchActivity | C20: TextView | D20: My account | E20: My account | F20: navigation_bar_item_small_label_view | G20: Duplicate ID | H20: my_account_label
A21: roomSearch_element_19 | B21: SearchActivity | C21: Button | D21: Enter your destination | G21: Missing ID | H21: enter_your_destination_btn
A22: roomSearch_element_20 | B22: SearchActivity | C22: Button | D22: Staying from Sun 28 Jun until Mon 29 Jun | G22: Missing ID | H22: staying_from_sun_28_jun_until_mon_29_jun_btn
A23: roomSearch_element_21 | B23: SearchActivity | C23: Button | D23: 1 room, 2 adults, 0 children | G23: Missing ID | H23: 1_room_2_adults_0_children_btn
A24: roomSearch_element_22 | B24: SearchActivity | C24: ImageView | D24: Messages | G24: Missing ID | H24: messages_icon
A25: roomSearch_element_23 | B25: SearchActivity | C25: ImageView | D25: Notifications | G25: Missing ID | H25: notifications_icon
A26: CarRental_element_1 | B26: SearchActivity | C26: ViewGroup | F26: facet_with_bui_booking_header_toolbar | G26: Unique ID | H26: { "key": "facetWithBuiBookingHeaderToolbarContainer", "androidValue": "facet_with_bui_booking_header_toolbar", "androidType": "id", "iosValue": "facet_with_bui_booking_header_toolbar", "iosType": "accessibilityId" }
A27: CarRental_element_2 | B27: SearchActivity | C27: TextView | D27: 1 | E27: 1 | F27: bubble | G27: Unique ID | H27: { "key": "bubbleLabel", "androidValue": "bubble", "androidType": "id", "iosValue": "bubble", "iosType": "accessibilityId" }
A28: CarRental_element_3 | B28: SearchActivity | C28: TextView | D28: Search | E28: Search | F28: navigation_bar_item_large_label_view | G28: Unique ID | H28: { "key": "navigationBarItemLargeLabelViewLabel", "androidValue": "navigation_bar_item_large_label_view", "androidType": "id", "iosValue": "navigation_bar_item_large_label_view", "iosType": "accessibilityId" }
A29: CarRental_element_4 | B29: SearchActivity | C29: ImageView | F29: facet_entry_point_item_icon | G29: Duplicate ID | H29: imageview_icon
A30: CarRental_element_5 | B30: SearchActivity | C30: ImageView | F30: facet_entry_point_item_icon | G30: Duplicate ID | H30: imageview_icon
A31: CarRental_element_6 | B31: SearchActivity | C31: ImageView | F31: facet_entry_point_item_icon | G31: Duplicate ID | H31: imageview_icon
A32: CarRental_element_7 | B32: SearchActivity | C32: ImageView | F32: facet_entry_point_item_icon | G32: Duplicate ID | H32: imageview_icon
A33: CarRental_element_8 | B33: SearchActivity | C33: ImageView | F33: navigation_bar_item_icon_view | G33: Duplicate ID | H33: imageview_icon
A34: CarRental_element_9 | B34: SearchActivity | C34: ImageView | F34: navigation_bar_item_icon_view | G34: Duplicate ID | H34: imageview_icon
A35: CarRental_element_10 | B35: SearchActivity | C35: ImageView | F35: navigation_bar_item_icon_view | G35: Duplicate ID | H35: imageview_icon
A36: CarRental_element_11 | B36: SearchActivity | C36: ImageView | F36: navigation_bar_item_icon_view | G36: Duplicate ID | H36: imageview_icon
A37: CarRental_element_12 | B37: SearchActivity | C37: TextView | D37: Stays | E37: Stays | F37: facet_entry_point_item_label | G37: Duplicate ID | H37: stays_label
A38: CarRental_element_13 | B38: SearchActivity | C38: TextView | D38: Car rental | E38: Car rental | F38: facet_entry_point_item_label | G38: Duplicate ID | H38: car_rental_label
A39: CarRental_element_14 | B39: SearchActivity | C39: TextView | D39: Taxi | E39: Taxi | F39: facet_entry_point_item_label | G39: Duplicate ID | H39: taxi_label
A40: CarRental_element_15 | B40: SearchActivity | C40: TextView | D40: Attractions | E40: Attractions | F40: facet_entry_point_item_label | G40: Duplicate ID | H40: attractions_label
...

Sheet Summary
A1: Accessibility ID — Özet Rapor
A3: Missing ID | B3: Undefined ID | C3: Duplicate ID | D3: Unique ID
A4: 11 | B4: 0 | C4: 30 | D4: 6
A5: %23 | B5: %0 | C5: %64 | D5: %13
A7: Sayfa Bazlı Dağılım
A8: Sayfa | B8: Missing ID | C8: Undefined ID | D8: Duplicate ID | E8: Unique ID | F8: TOPLAM
A9: roomSearch | B9: 5 | C9: 0 | D9: 15 | E9: 3 | F9: 23
A10: CarRental | B10: 6 | C10: 0 | D10: 15 | E10: 3 | F10: 24
A11: TOPLAM | B11: 11 | C11: 0 | D11: 30 | E11: 6 | F11: 47

Sheet Task
A1: ID Eklenecek Elementler — Waiting Dev (35 adet)
A2: Element ID | B2: Page | C2: Type | D2: Label / Text | E2: Value | F2: Resource ID | G2: Status | H2: New Status | I2: AI Suggestion
A3: roomSearch_element_10 | B3: SearchActivity | C3: ImageView | F3: navigation_bar_item_icon_view | G3: Duplicate ID | H3: =roomSearch!H12 | I3: =roomSearch!I12
A4: roomSearch_element_11 | B4: SearchActivity | C4: ImageView | F4: navigation_bar_item_icon_view | G4: Duplicate ID | H4: =roomSearch!H13 | I4: =roomSearch!I13
A5: roomSearch_element_12 | B5: SearchActivity | C5: TextView | D5: Stays | E5: Stays | F5: facet_entry_point_item_label | G5: Duplicate ID | H5: =roomSearch!H14 | I5: =roomSearch!I14
A6: roomSearch_element_13 | B6: SearchActivity | C6: TextView | D6: Car rental | E6: Car rental | F6: facet_entry_point_item_label | G6: Duplicate ID | H6: =roomSearch!H15 | I6: =roomSearch!I15
A7: roomSearch_element_14 | B7: SearchActivity | C7: TextView | D7: Taxi | E7: Taxi | F7: facet_entry_point_item_label | G7: Duplicate ID | H7: =roomSearch!H16 | I7: =roomSearch!I16
A8: roomSearch_element_15 | B8: SearchActivity | C8: TextView | D8: Attractions | E8: Attractions | F8: facet_entry_point_item_label | G8: Duplicate ID | H8: =roomSearch!H17 | I8: =roomSearch!I17
A9: roomSearch_element_16 | B9: SearchActivity | C9: TextView | D9: Saved | E9: Saved | F9: navigation_bar_item_small_label_view | G9: Duplicate ID | H9: =roomSearch!H18 | I9: =roomSearch!I18
A10: roomSearch_element_17 | B10: SearchActivity | C10: TextView | D10: Bookings | E10: Bookings | F10: navigation_bar_item_small_label_view | G10: Duplicate ID | H10: =roomSearch!H19 | I10: =roomSearch!I19
A11: roomSearch_element_18 | B11: SearchActivity | C11: TextView | D11: My account | E11: My account | F11: navigation_bar_item_small_label_view | G11: Duplicate ID | H11: =roomSearch!H20 | I11: =roomSearch!I20
A12: roomSearch_element_19 | B12: SearchActivity | C12: Button | D12: Enter your destination | G12: Missing ID | H12: =roomSearch!H21 | I12: =roomSearch!I21
A13: roomSearch_element_20 | B13: SearchActivity | C13: Button | D13: Staying from Sun 28 Jun until Mon 29 Jun | G13: Missing ID | H13: =roomSearch!H22 | I13: =roomSearch!I22
A14: roomSearch_element_21 | B14: SearchActivity | C14: Button | D14: 1 room, 2 adults, 0 children | G14: Missing ID | H14: =roomSearch!H23 | I14: =roomSearch!I23
A15: roomSearch_element_22 | B15: SearchActivity | C15: ImageView | D15: Messages | G15: Missing ID | H15: =roomSearch!H24 | I15: =roomSearch!I24
A16: roomSearch_element_23 | B16: SearchActivity | C16: ImageView | D16: Notifications | G16: Missing ID | H16: =roomSearch!H25 | I16: =roomSearch!I25
A17: CarRental_element_4 | B17: SearchActivity | C17: ImageView | F17: facet_entry_point_item_icon | G17: Duplicate ID | H17: =CarRental!H6 | I17: =CarRental!I6
A18: CarRental_element_5 | B18: SearchActivity | C18: ImageView | F18: facet_entry_point_item_icon | G18: Duplicate ID | H18: =CarRental!H7 | I18: =CarRental!I7
A19: CarRental_element_6 | B19: SearchActivity | C19: ImageView | F19: facet_entry_point_item_icon | G19: Duplicate ID | H19: =CarRental!H8 | I19: =CarRental!I8
A20: CarRental_element_7 | B20: SearchActivity | C20: ImageView | F20: facet_entry_point_item_icon | G20: Duplicate ID | H20: =CarRental!H9 | I20: =CarRental!I9
A21: CarRental_element_8 | B21: SearchActivity | C21: ImageView | F21: navigation_bar_item_icon_view | G21: Duplicate ID | H21: =CarRental!H10 | I21: =CarRental!I10
A22: CarRental_element_9 | B22: SearchActivity | C22: ImageView | F22: navigation_bar_item_icon_view | G22: Duplicate ID | H22: =CarRental!H11 | I22: =CarRental!I11
A23: CarRental_element_10 | B23: SearchActivity | C23: ImageView | F23: navigation_bar_item_icon_view | G23: Duplicate ID | H23: =CarRental!H12 | I23: =CarRental!I12
A24: CarRental_element_11 | B24: SearchActivity | C24: ImageView | F24: navigation_bar_item_icon_view | G24: Duplicate ID | H24: =CarRental!H13 | I24: =CarRental!I13
A25: CarRental_element_12 | B25: SearchActivity | C25: TextView | D25: Stays | E25: Stays | F25: facet_entry_point_item_label | G25: Duplicate ID | H25: =CarRental!H14 | I25: =CarRental!I14
A26: CarRental_element_13 | B26: SearchActivity | C26: TextView | D26: Car rental | E26: Car rental | F26: facet_entry_point_item_label | G26: Duplicate ID | H26: =CarRental!H15 | I26: =CarRental!I15
A27: CarRental_element_14 | B27: SearchActivity | C27: TextView | D27: Taxi | E27: Taxi | F27: facet_entry_point_item_label | G27: Duplicate ID | H27: =CarRental!H16 | I27: =CarRental!I16
A28: CarRental_element_15 | B28: SearchActivity | C28: TextView | D28: Attractions | E28: Attractions | F28: facet_entry_point_item_label | G28: Duplicate ID | H28: =CarRental!H17 | I28: =CarRental!I17
A29: CarRental_element_16 | B29: SearchActivity | C29: TextView | D29: Saved | E29: Saved | F29: navigation_bar_item_small_label_view | G29: Duplicate ID | H29: =CarRental!H18 | I29: =CarRental!I18
A30: CarRental_element_17 | B30: SearchActivity | C30: TextView | D30: Bookings | E30: Bookings | F30: navigation_bar_item_small_label_view | G30: Duplicate ID | H30: =CarRental!H19 | I30: =CarRental!I19
A31: CarRental_element_18 | B31: SearchActivity | C31: TextView | D31: My account | E31: My account | F31: navigation_bar_item_small_label_view | G31: Duplicate ID | H31: =CarRental!H20 | I31: =CarRental!I20
A32: CarRental_element_19 | B32: SearchActivity | C32: Button | D32: Enter a pick-up location | G32: Missing ID | H32: =CarRental!H21 | I32: =CarRental!I21
A33: CarRental_element_20 | B33: SearchActivity | C33: Button | D33: Pick-up 29 Jun 10:00, Drop-off 02 Jul 10:00 | G33: Missing ID | H33: =CarRental!H22 | I33: =CarRental!I22
A34: CarRental_element_21 | B34: SearchActivity | C34: Button | D34: Enter the driver's age | G34: Missing ID | H34: =CarRental!H23 | I34: =CarRental!I23
A35: CarRental_element_22 | B35: SearchActivity | C35: View | D35: Selected, you will return the car to the same location | G35: Missing ID | H35: =CarRental!H24 | I35: =CarRental!I24
A36: CarRental_element_23 | B36: SearchActivity | C36: ImageView | D36: Messages | G36: Missing ID | H36: =CarRental!H25 | I36: =CarRental!I25
A37: CarRental_element_24 | B37: SearchActivity | C37: ImageView | D37: Notifications | G37: Missing ID | H37: =CarRental!H26 | I37: =CarRental!I26

Sheet roomSearch
A1: roomSearch | 28.06.2026 20:29 | ANDROID | K1: 📸 roomSearch
A2: Element ID | B2: Page | C2: Type | D2: Label / Text | E2: Value | F2: Resource ID | G2: Status | H2: New Status | I2: AI Suggestion
A3: roomSearch_element_1 | B3: SearchActivity | C3: ViewGroup | F3: facet_with_bui_booking_header_toolbar | G3: Unique ID | I3: { "key": "facetWithBuiBookingHeaderToolbarContainer", "androidValue": "facet_with_bui_booking_header_toolbar", "androidType": "id", "iosValue": "facet_with_bui_booking_header_toolbar", "iosType": "accessibilityId" }
A4: roomSearch_element_2 | B4: SearchActivity | C4: TextView | D4: 1 | E4: 1 | F4: bubble | G4: Unique ID | I4: { "key": "bubbleLabel", "androidValue": "bubble", "androidType": "id", "iosValue": "bubble", "iosType": "accessibilityId" }
A5: roomSearch_element_3 | B5: SearchActivity | C5: TextView | D5: Search | E5: Search | F5: navigation_bar_item_large_label_view | G5: Unique ID | I5: { "key": "navigationBarItemLargeLabelViewLabel", "androidValue": "navigation_bar_item_large_label_view", "androidType": "id", "iosValue": "navigation_bar_item_large_label_view", "iosType": "accessibilityId" }
A6: roomSearch_element_4 | B6: SearchActivity | C6: ImageView | F6: facet_entry_point_item_icon | G6: Duplicate ID | H6: ID Added v2 | I6: facet_entry_point_item_icon_room
A7: roomSearch_element_5 | B7: SearchActivity | C7: ImageView | F7: facet_entry_point_item_icon | G7: Duplicate ID | H7: ID Added v2 | I7: facet_entry_point_item_icon_car
A8: roomSearch_element_6 | B8: SearchActivity | C8: ImageView | F8: facet_entry_point_item_icon | G8: Duplicate ID | H8: ID Added v2 | I8: facet_entry_point_item_icon_taxi
A9: roomSearch_element_7 | B9: SearchActivity | C9: ImageView | F9: facet_entry_point_item_icon | G9: Duplicate ID | H9: ID Added v2 | I9: imageview_icon
A10: roomSearch_element_8 | B10: SearchActivity | C10: ImageView | F10: navigation_bar_item_icon_view | G10: Duplicate ID | H10: ID Added v2 | I10: imageview_icon
A11: roomSearch_element_9 | B11: SearchActivity | C11: ImageView | F11: navigation_bar_item_icon_view | G11: Duplicate ID | H11: ID Added v2 | I11: imageview_icon
A12: roomSearch_element_10 | B12: SearchActivity | C12: ImageView | F12: navigation_bar_item_icon_view | G12: Duplicate ID | H12: ID Must Be Added (Waiting Dev) | I12: imageview_icon
A13: roomSearch_element_11 | B13: SearchActivity | C13: ImageView | F13: navigation_bar_item_icon_view | G13: Duplicate ID | H13: ID Must Be Added (Waiting Dev) | I13: imageview_icon
A14: roomSearch_element_12 | B14: SearchActivity | C14: TextView | D14: Stays | E14: Stays | F14: facet_entry_point_item_label | G14: Duplicate ID | H14: ID Must Be Added (Waiting Dev) | I14: stays_label
A15: roomSearch_element_13 | B15: SearchActivity | C15: TextView | D15: Car rental | E15: Car rental | F15: facet_entry_point_item_label | G15: Duplicate ID | H15: ID Must Be Added (Waiting Dev) | I15: car_rental_label
A16: roomSearch_element_14 | B16: SearchActivity | C16: TextView | D16: Taxi | E16: Taxi | F16: facet_entry_point_item_label | G16: Duplicate ID | H16: ID Must Be Added (Waiting Dev) | I16: taxi_label
A17: roomSearch_element_15 | B17: SearchActivity | C17: TextView | D17: Attractions | E17: Attractions | F17: facet_entry_point_item_label | G17: Duplicate ID | H17: ID Must Be Added (Waiting Dev) | I17: attractions_label
A18: roomSearch_element_16 | B18: SearchActivity | C18: TextView | D18: Saved | E18: Saved | F18: navigation_bar_item_small_label_view | G18: Duplicate ID | H18: ID Must Be Added (Waiting Dev) | I18: saved_label
A19: roomSearch_element_17 | B19: SearchActivity | C19: TextView | D19: Bookings | E19: Bookings | F19: navigation_bar_item_small_label_view | G19: Duplicate ID | H19: ID Must Be Added (Waiting Dev) | I19: bookings_label
A20: roomSearch_element_18 | B20: SearchActivity | C20: TextView | D20: My account | E20: My account | F20: navigation_bar_item_small_label_view | G20: Duplicate ID | H20: ID Must Be Added (Waiting Dev) | I20: my_account_label
A21: roomSearch_element_19 | B21: SearchActivity | C21: Button | D21: Enter your destination | G21: Missing ID | H21: ID Must Be Added (Waiting Dev) | I21: enter_your_destination_btn
A22: roomSearch_element_20 | B22: SearchActivity | C22: Button | D22: Staying from Sun 28 Jun until Mon 29 Jun | G22: Missing ID | H22: ID Must Be Added (Waiting Dev) | I22: staying_from_sun_28_jun_until_mon_29_jun_btn
A23: roomSearch_element_21 | B23: SearchActivity | C23: Button | D23: 1 room, 2 adults, 0 children | G23: Missing ID | H23: ID Must Be Added (Waiting Dev) | I23: 1_room_2_adults_0_children_btn
A24: roomSearch_element_22 | B24: SearchActivity | C24: ImageView | D24: Messages | G24: Missing ID | H24: ID Must Be Added (Waiting Dev) | I24: messages_icon
A25: roomSearch_element_23 | B25: SearchActivity | C25: ImageView | D25: Notifications | G25: Missing ID | H25: ID Must Be Added (Waiting Dev) | I25: notifications_icon

Sheet CarRental
A1: CarRental | 28.06.2026 20:34 | ANDROID | K1: 📸 CarRental
A2: Element ID | B2: Page | C2: Type | D2: Label / Text | E2: Value | F2: Resource ID | G2: Status | H2: New Status | I2: AI Suggestion
A3: CarRental_element_1 | B3: SearchActivity | C3: ViewGroup | F3: facet_with_bui_booking_header_toolbar | G3: Unique ID | I3: { "key": "facetWithBuiBookingHeaderToolbarContainer", "androidValue": "facet_with_bui_booking_header_toolbar", "androidType": "id", "iosValue": "facet_with_bui_booking_header_toolbar", "iosType": "accessibilityId" }
A4: CarRental_element_2 | B4: SearchActivity | C4: TextView | D4: 1 | E4: 1 | F4: bubble | G4: Unique ID | I4: { "key": "bubbleLabel", "androidValue": "bubble", "androidType": "id", "iosValue": "bubble", "iosType": "accessibilityId" }
A5: CarRental_element_3 | B5: SearchActivity | C5: TextView | D5: Search | E5: Search | F5: navigation_bar_item_large_label_view | G5: Unique ID | I5: { "key": "navigationBarItemLargeLabelViewLabel", "androidValue": "navigation_bar_item_large_label_view", "androidType": "id", "iosValue": "navigation_bar_item_large_label_view", "iosType": "accessibilityId" }
A6: CarRental_element_4 | B6: SearchActivity | C6: ImageView | F6: facet_entry_point_item_icon | G6: Duplicate ID | H6: ID Must Be Added (Waiting Dev) | I6: imageview_icon
A7: CarRental_element_5 | B7: SearchActivity | C7: ImageView | F7: facet_entry_point_item_icon | G7: Duplicate ID | H7: ID Must Be Added (Waiting Dev) | I7: imageview_icon
A8: CarRental_element_6 | B8: SearchActivity | C8: ImageView | F8: facet_entry_point_item_icon | G8: Duplicate ID | H8: ID Must Be Added (Waiting Dev) | I8: imageview_icon
A9: CarRental_element_7 | B9: SearchActivity | C9: ImageView | F9: facet_entry_point_item_icon | G9: Duplicate ID | H9: ID Must Be Added (Waiting Dev) | I9: imageview_icon
A10: CarRental_element_8 | B10: SearchActivity | C10: ImageView | F10: navigation_bar_item_icon_view | G10: Duplicate ID | H10: ID Must Be Added (Waiting Dev) | I10: imageview_icon
A11: CarRental_element_9 | B11: SearchActivity | C11: ImageView | F11: navigation_bar_item_icon_view | G11: Duplicate ID | H11: ID Must Be Added (Waiting Dev) | I11: imageview_icon
A12: CarRental_element_10 | B12: SearchActivity | C12: ImageView | F12: navigation_bar_item_icon_view | G12: Duplicate ID | H12: ID Must Be Added (Waiting Dev) | I12: imageview_icon
A13: CarRental_element_11 | B13: SearchActivity | C13: ImageView | F13: navigation_bar_item_icon_view | G13: Duplicate ID | H13: ID Must Be Added (Waiting Dev) | I13: imageview_icon
A14: CarRental_element_12 | B14: SearchActivity | C14: TextView | D14: Stays | E14: Stays | F14: facet_entry_point_item_label | G14: Duplicate ID | H14: ID Must Be Added (Waiting Dev) | I14: stays_label
A15: CarRental_element_13 | B15: SearchActivity | C15: TextView | D15: Car rental | E15: Car rental | F15: facet_entry_point_item_label | G15: Duplicate ID | H15: ID Must Be Added (Waiting Dev) | I15: car_rental_label
A16: CarRental_element_14 | B16: SearchActivity | C16: TextView | D16: Taxi | E16: Taxi | F16: facet_entry_point_item_label | G16: Duplicate ID | H16: ID Must Be Added (Waiting Dev) | I16: taxi_label
A17: CarRental_element_15 | B17: SearchActivity | C17: TextView | D17: Attractions | E17: Attractions | F17: facet_entry_point_item_label | G17: Duplicate ID | H17: ID Must Be Added (Waiting Dev) | I17: attractions_label
A18: CarRental_element_16 | B18: SearchActivity | C18: TextView | D18: Saved | E18: Saved | F18: navigation_bar_item_small_label_view | G18: Duplicate ID | H18: ID Must Be Added (Waiting Dev) | I18: saved_label
A19: CarRental_element_17 | B19: SearchActivity | C19: TextView | D19: Bookings | E19: Bookings | F19: navigation_bar_item_small_label_view | G19: Duplicate ID | H19: ID Must Be Added (Waiting Dev) | I19: bookings_label
A20: CarRental_element_18 | B20: SearchActivity | C20: TextView | D20: My account | E20: My account | F20: navigation_bar_item_small_label_view | G20: Duplicate ID | H20: ID Must Be Added (Waiting Dev) | I20: my_account_label
A21: CarRental_element_19 | B21: SearchActivity | C21: Button | D21: Enter a pick-up location | G21: Missing ID | H21: ID Must Be Added (Waiting Dev) | I21: enter_a_pick_up_location_btn
A22: CarRental_element_20 | B22: SearchActivity | C22: Button | D22: Pick-up 29 Jun 10:00, Drop-off 02 Jul 10:00 | G22: Missing ID | H22: ID Must Be Added (Waiting Dev) | I22: pick_up_29_jun_10_00_drop_off_02_jul_10_00_btn
A23: CarRental_element_21 | B23: SearchActivity | C23: Button | D23: Enter the driver's age | G23: Missing ID | H23: ID Must Be Added (Waiting Dev) | I23: enter_the_driver_s_age_btn
A24: CarRental_element_22 | B24: SearchActivity | C24: View | D24: Selected, you will return the car to the same location | G24: Missing ID | H24: ID Must Be Added (Waiting Dev) | I24: selected_you_will_return_the_car_to_the_same_location_container
A25: CarRental_element_23 | B25: SearchActivity | C25: ImageView | D25: Messages | G25: Missing ID | H25: ID Must Be Added (Waiting Dev) | I25: messages_icon
A26: CarRental_element_24 | B26: SearchActivity | C26: ImageView | D26: Notifications | G26: Missing ID | H26: ID Must Be Added (Waiting Dev) | I26: notifications_icon
